[2018-Oct-12 14:47:11][AutoplacementQPCR384][CRITICAL] Encountered a TypeError exception: 'int' object is not iterable
[2018-Oct-12 14:47:11][AutoplacementQPCR384][ERROR] Stack trace below:
Traceback (most recent call last):
  File "C:\Users\dforth\PycharmProjects\untitled\venv\lib\site-packages\clarity_scripts-0.9.dev0-py3.6.egg\EPPs\common.py", line 126, in run
    self._run()
  File "C:\Users\dforth\PycharmProjects\clarity_scripts\scripts\autoplacement_qpcr_384.py", line 105, in _run
    for replicate in replicate_counter:
TypeError: 'int' object is not iterable

[2018-Oct-12 14:47:34][AutoplacementQPCR384][CRITICAL] Encountered a TypeError exception: 'int' object is not iterable
[2018-Oct-12 14:47:34][AutoplacementQPCR384][ERROR] Stack trace below:
Traceback (most recent call last):
  File "C:\Users\dforth\PycharmProjects\untitled\venv\lib\site-packages\clarity_scripts-0.9.dev0-py3.6.egg\EPPs\common.py", line 126, in run
    self._run()
  File "C:\Users\dforth\PycharmProjects\clarity_scripts\scripts\autoplacement_qpcr_384.py", line 105, in _run
    for replicate in replicate_counter:
TypeError: 'int' object is not iterable

[2018-Oct-12 14:48:26][AutoplacementQPCR384][CRITICAL] Encountered a NameError exception: name 'replicate' is not defined
[2018-Oct-12 14:48:26][AutoplacementQPCR384][ERROR] Stack trace below:
Traceback (most recent call last):
  File "C:\Users\dforth\PycharmProjects\untitled\venv\lib\site-packages\clarity_scripts-0.9.dev0-py3.6.egg\EPPs\common.py", line 126, in run
    self._run()
  File "C:\Users\dforth\PycharmProjects\clarity_scripts\scripts\autoplacement_qpcr_384.py", line 108, in _run
    output_placement_list.append((outputs_dict[str(replicate) + row + ":" + column],
NameError: name 'replicate' is not defined

[2018-Oct-12 14:48:50][AutoplacementQPCR384][CRITICAL] Encountered a HTTPError exception: 400: The request contains duplicate artifacts: [92-166845, 92-166845, 92-166844, 92-166844, 92-166846, 92-166846]
[2018-Oct-12 14:48:50][AutoplacementQPCR384][ERROR] Stack trace below:
Traceback (most recent call last):
  File "C:\Users\dforth\PycharmProjects\untitled\venv\lib\site-packages\clarity_scripts-0.9.dev0-py3.6.egg\EPPs\common.py", line 126, in run
    self._run()
  File "C:\Users\dforth\PycharmProjects\clarity_scripts\scripts\autoplacement_qpcr_384.py", line 124, in _run
    self.process.step.set_placements(output_container_list, output_placement_list)
  File "C:\Users\dforth\PycharmProjects\untitled\venv\lib\site-packages\pyclarity_lims\entities.py", line 946, in set_placements
    self.placements.root = self.placements.post()
  File "C:\Users\dforth\PycharmProjects\untitled\venv\lib\site-packages\pyclarity_lims\entities.py", line 96, in post
    return self.lims.post(self.uri, data)
  File "C:\Users\dforth\PycharmProjects\untitled\venv\lib\site-packages\pyclarity_lims\lims.py", line 166, in post
    return self.parse_response(r, accept_status_codes=[200, 201, 202])
  File "C:\Users\dforth\PycharmProjects\untitled\venv\lib\site-packages\pyclarity_lims\lims.py", line 209, in parse_response
    self.validate_response(response, accept_status_codes)
  File "C:\Users\dforth\PycharmProjects\untitled\venv\lib\site-packages\pyclarity_lims\lims.py", line 202, in validate_response
    raise requests.exceptions.HTTPError(message)
requests.exceptions.HTTPError: 400: The request contains duplicate artifacts: [92-166845, 92-166845, 92-166844, 92-166844, 92-166846, 92-166846]

