[2018-Nov-06 10:28:36][GenerateHamiltonInputCFP][CRITICAL] Encountered a FileNotFoundError exception: [Errno 2] No such file or directory: '/mnt/EGCGgeneral/HAMILTON_INPUTS/KAPA_MAKE_CFP/KAPA_MAKE_CFP.csv'
[2018-Nov-06 10:28:36][GenerateHamiltonInputCFP][ERROR] Stack trace below:
Traceback (most recent call last):
  File "C:\Users\dforth\PycharmProjects\untitled\venv\lib\site-packages\clarity_scripts-0.9.dev0-py3.6.egg\EPPs\common.py", line 126, in run
    self._run()
  File "C:\Users\dforth\PycharmProjects\clarity_scripts\scripts\generate_hamilton_input_cfp.py", line 111, in _run
    with open(self.shared_drive_path + 'KAPA_MAKE_CFP.csv', 'w') as csvFile:
FileNotFoundError: [Errno 2] No such file or directory: '/mnt/EGCGgeneral/HAMILTON_INPUTS/KAPA_MAKE_CFP/KAPA_MAKE_CFP.csv'

[2018-Nov-06 10:28:56][GenerateHamiltonInputCFP][CRITICAL] Encountered a FileNotFoundError exception: [Errno 2] No such file or directory: '../HAMILTON_INPUTS/KAPA_MAKE_CFP/KAPA_MAKE_CFP.csv'
[2018-Nov-06 10:28:56][GenerateHamiltonInputCFP][ERROR] Stack trace below:
Traceback (most recent call last):
  File "C:\Users\dforth\PycharmProjects\untitled\venv\lib\site-packages\clarity_scripts-0.9.dev0-py3.6.egg\EPPs\common.py", line 126, in run
    self._run()
  File "C:\Users\dforth\PycharmProjects\clarity_scripts\scripts\generate_hamilton_input_cfp.py", line 111, in _run
    with open(self.shared_drive_path + 'KAPA_MAKE_CFP.csv', 'w') as csvFile:
FileNotFoundError: [Errno 2] No such file or directory: '../HAMILTON_INPUTS/KAPA_MAKE_CFP/KAPA_MAKE_CFP.csv'

[2018-Nov-06 10:29:44][GenerateHamiltonInputCFP][CRITICAL] Encountered a OSError exception: [Errno 22] Invalid argument: 'C:\\Users\\dforth\\PycharmProjects\\clarity_scripts\\scripts"KAPA_MAKE_CFP.csv'
[2018-Nov-06 10:29:44][GenerateHamiltonInputCFP][ERROR] Stack trace below:
Traceback (most recent call last):
  File "C:\Users\dforth\PycharmProjects\untitled\venv\lib\site-packages\clarity_scripts-0.9.dev0-py3.6.egg\EPPs\common.py", line 126, in run
    self._run()
  File "C:\Users\dforth\PycharmProjects\clarity_scripts\scripts\generate_hamilton_input_cfp.py", line 111, in _run
    with open(self.shared_drive_path + 'KAPA_MAKE_CFP.csv', 'w') as csvFile:
OSError: [Errno 22] Invalid argument: 'C:\\Users\\dforth\\PycharmProjects\\clarity_scripts\\scripts"KAPA_MAKE_CFP.csv'

[2018-Nov-06 11:43:44][GenerateHamiltonInputNTP][CRITICAL] Encountered a KeyError exception: 'NTP Library Volume (uL)'
[2018-Nov-06 11:43:44][GenerateHamiltonInputNTP][ERROR] Stack trace below:
Traceback (most recent call last):
  File "C:\Users\dforth\PycharmProjects\untitled\venv\lib\site-packages\clarity_scripts-0.9.dev0-py3.6.egg\EPPs\common.py", line 133, in run
    return self._run()
  File "C:\Users\dforth\PycharmProjects\untitled\venv\lib\site-packages\clarity_scripts-0.9.dev0-py3.6.egg\EPPs\common.py", line 277, in _run
    csv_array = self.generate_csv_array()
  File "C:\Users\dforth\PycharmProjects\untitled\venv\lib\site-packages\clarity_scripts-0.9.dev0-py3.6.egg\EPPs\common.py", line 253, in generate_csv_array
    csv_dict = self._generate_csv_dict()
  File "C:\Users\dforth\PycharmProjects\clarity_scripts\scripts\generate_hamilton_input_ntp.py", line 51, in _generate_csv_dict
    output.udf['NTP Library Volume (uL)'], rsb_barcode, output.udf['NTP RSB Volume (uL)']
KeyError: 'NTP Library Volume (uL)'

