[2018-Oct-12 11:48:19][AutoplacementQPCR384][CRITICAL] Encountered a HTTPError exception: 404: Process not found: 24-3076
[2018-Oct-12 11:48:19][AutoplacementQPCR384][ERROR] Stack trace below:
Traceback (most recent call last):
  File "C:\Users\dforth\PycharmProjects\untitled\venv\lib\site-packages\clarity_scripts-0.9.dev0-py3.6.egg\EPPs\common.py", line 126, in run
    self._run()
  File "C:\Users\dforth\PycharmProjects\clarity_scripts\scripts\autoplacement_qpcr_384.py", line 17, in _run
    all_inputs = self.process.all_inputs(unique=True)
  File "C:\Users\dforth\PycharmProjects\untitled\venv\lib\site-packages\pyclarity_lims\entities.py", line 474, in all_inputs
    ids = [io[0]['limsid'] for io in self.input_output_maps]
  File "C:\Users\dforth\PycharmProjects\untitled\venv\lib\site-packages\pyclarity_lims\descriptors.py", line 949, in __get__
    instance.get()
  File "C:\Users\dforth\PycharmProjects\untitled\venv\lib\site-packages\pyclarity_lims\entities.py", line 86, in get
    self.root = self.lims.get(self.uri)
  File "C:\Users\dforth\PycharmProjects\untitled\venv\lib\site-packages\pyclarity_lims\lims.py", line 96, in get
    return self.parse_response(r)
  File "C:\Users\dforth\PycharmProjects\untitled\venv\lib\site-packages\pyclarity_lims\lims.py", line 209, in parse_response
    self.validate_response(response, accept_status_codes)
  File "C:\Users\dforth\PycharmProjects\untitled\venv\lib\site-packages\pyclarity_lims\lims.py", line 202, in validate_response
    raise requests.exceptions.HTTPError(message)
requests.exceptions.HTTPError: 404: Process not found: 24-3076

[2018-Oct-12 11:48:31][AutoplacementQPCR384][CRITICAL] Encountered a IndexError exception: list index out of range
[2018-Oct-12 11:48:31][AutoplacementQPCR384][ERROR] Stack trace below:
Traceback (most recent call last):
  File "C:\Users\dforth\PycharmProjects\untitled\venv\lib\site-packages\clarity_scripts-0.9.dev0-py3.6.egg\EPPs\common.py", line 126, in run
    self._run()
  File "C:\Users\dforth\PycharmProjects\clarity_scripts\scripts\autoplacement_qpcr_384.py", line 77, in _run
    output_placement_list.append((standards_dict[key],(output_container_list[0],plate_layout[well_counter])))
IndexError: list index out of range

[2018-Oct-12 11:48:58][AutoplacementQPCR384][CRITICAL] Encountered a IndexError exception: list index out of range
[2018-Oct-12 11:48:58][AutoplacementQPCR384][ERROR] Stack trace below:
Traceback (most recent call last):
  File "C:\Users\dforth\PycharmProjects\untitled\venv\lib\site-packages\clarity_scripts-0.9.dev0-py3.6.egg\EPPs\common.py", line 126, in run
    self._run()
  File "C:\Users\dforth\PycharmProjects\clarity_scripts\scripts\autoplacement_qpcr_384.py", line 77, in _run
    output_placement_list.append((standards_dict[key],(output_container_list[0],plate_layout[well_counter])))
IndexError: list index out of range

[2018-Oct-12 11:50:25][AutoplacementQPCR384][CRITICAL] Encountered a IndexError exception: list index out of range
[2018-Oct-12 11:50:25][AutoplacementQPCR384][ERROR] Stack trace below:
Traceback (most recent call last):
  File "C:\Users\dforth\PycharmProjects\untitled\venv\lib\site-packages\clarity_scripts-0.9.dev0-py3.6.egg\EPPs\common.py", line 126, in run
    self._run()
  File "C:\Users\dforth\PycharmProjects\clarity_scripts\scripts\autoplacement_qpcr_384.py", line 78, in _run
    output_placement_list.append((standards_dict[key],(output_container_list[0],plate_layout[well_counter])))
IndexError: list index out of range

[2018-Oct-12 11:51:22][AutoplacementQPCR384][CRITICAL] Encountered a IndexError exception: list index out of range
[2018-Oct-12 11:51:22][AutoplacementQPCR384][ERROR] Stack trace below:
Traceback (most recent call last):
  File "C:\Users\dforth\PycharmProjects\untitled\venv\lib\site-packages\clarity_scripts-0.9.dev0-py3.6.egg\EPPs\common.py", line 126, in run
    self._run()
  File "C:\Users\dforth\PycharmProjects\clarity_scripts\scripts\autoplacement_qpcr_384.py", line 78, in _run
    output_placement_list.append((standards_dict[key],(output_container_list[0],plate_layout[well_counter])))
IndexError: list index out of range

