[2018-Nov-15 08:45:17][SpectramaxOutput][CRITICAL] Encountered a AssertionError exception: Badly formed spectramax file: tried to add coord H9 for sample 72 to plate LP9181114-QNT
[2018-Nov-15 08:45:17][SpectramaxOutput][ERROR] Stack trace below:
Traceback (most recent call last):
  File "C:\Users\dforth\PycharmProjects\untitled\venv\lib\site-packages\clarity_scripts-0.9.dev0-py3.6.egg\EPPs\common.py", line 133, in run
    return self._run()
  File "C:\Users\dforth\PycharmProjects\clarity_scripts\scripts\parse_spectramax_seq_plate_quant.py", line 118, in _run
    self.assign_samples_to_plates()
  File "C:\Users\dforth\PycharmProjects\clarity_scripts\scripts\parse_spectramax_seq_plate_quant.py", line 60, in assign_samples_to_plates
    coord, i, plate_name
AssertionError: Badly formed spectramax file: tried to add coord H9 for sample 72 to plate LP9181114-QNT

[2018-Nov-15 08:51:40][SpectramaxOutput][CRITICAL] Encountered a ValueError exception: could not convert string to float: 
[2018-Nov-15 08:51:40][SpectramaxOutput][ERROR] Stack trace below:
Traceback (most recent call last):
  File "C:\Users\dforth\PycharmProjects\untitled\venv\lib\site-packages\clarity_scripts-0.9.dev0-py3.6.egg\EPPs\common.py", line 133, in run
    return self._run()
  File "C:\Users\dforth\PycharmProjects\clarity_scripts\scripts\parse_spectramax_seq_plate_quant.py", line 117, in _run
    self.parse_spectramax_file()
  File "C:\Users\dforth\PycharmProjects\clarity_scripts\scripts\parse_spectramax_seq_plate_quant.py", line 41, in parse_spectramax_file
    self.sample_concs[int(split_line[0])] = (split_line[1], float(split_line[3]))
ValueError: could not convert string to float: 

[2018-Nov-15 08:52:52][SpectramaxOutput][CRITICAL] Encountered a ValueError exception: could not convert string to float: 
[2018-Nov-15 08:52:52][SpectramaxOutput][ERROR] Stack trace below:
Traceback (most recent call last):
  File "C:\Users\dforth\PycharmProjects\untitled\venv\lib\site-packages\clarity_scripts-0.9.dev0-py3.6.egg\EPPs\common.py", line 133, in run
    return self._run()
  File "C:\Users\dforth\PycharmProjects\clarity_scripts\scripts\parse_spectramax_seq_plate_quant.py", line 118, in _run
    self.parse_spectramax_file()
  File "C:\Users\dforth\PycharmProjects\clarity_scripts\scripts\parse_spectramax_seq_plate_quant.py", line 42, in parse_spectramax_file
    self.sample_concs[int(split_line[0])] = (split_line[1], float(split_line[3]))
ValueError: could not convert string to float: 

[2018-Nov-15 08:54:55][SpectramaxOutput][INFO] Updating step 24-31255 with data: defaultdict(<class 'dict'>, {'LP9181114-QNT': {'A4': 11.668, 'B4': 12.953, 'C4': 11.956, 'D4': 14.602, 'E4': 15.004, 'F4': 13.887, 'G4': 9.784, 'H4': 9.227, 'A5': 9.264, 'B5': 17.582, 'C5': 12.502, 'D5': 8.349, 'E5': 19.791, 'F5': 12.696, 'G5': 13.008, 'H5': 12.371, 'A6': 13.612, 'B6': 14.669, 'C6': 14.631, 'D6': 15.86, 'E6': 13.383, 'F6': 9.6, 'G6': 9.344, 'A7': 13.487, 'B7': 18.704, 'C7': 17.042, 'D7': 10.437, 'E7': 9.78, 'F7': 51.478, 'G7': 29.193, 'H7': 40.868, 'A8': 31.263, 'B8': 92.617, 'C8': 24.526, 'D8': 20.771, 'E8': 15.419, 'F8': 13.558, 'G8': 13.504, 'H8': 20.026, 'A9': 20.408, 'B9': 14.256, 'C9': 14.809, 'D9': 13.044, 'E9': 16.158, 'F9': 17.959, 'G9': 14.0, 'A10': 16.957, 'B10': 10.44, 'C10': 19.174, 'D10': 14.89, 'E10': 13.281, 'F10': 18.997, 'G10': 15.905, 'H10': 11.266, 'A11': 17.499, 'B11': 19.764, 'C11': 16.318, 'D11': 10.108, 'E11': 17.18, 'F11': 18.287, 'G11': 15.628, 'H11': 15.328, 'A12': 10.231, 'B12': 18.013, 'C12': 17.457, 'D12': 16.377, 'E12': 12.438, 'F12': 15.503, 'G12': 21.822}})
[2018-Nov-15 08:54:55][SpectramaxOutput][CRITICAL] Encountered a NameError exception: name 'column_list' is not defined
[2018-Nov-15 08:54:55][SpectramaxOutput][ERROR] Stack trace below:
Traceback (most recent call last):
  File "C:\Users\dforth\PycharmProjects\untitled\venv\lib\site-packages\clarity_scripts-0.9.dev0-py3.6.egg\EPPs\common.py", line 133, in run
    return self._run()
  File "C:\Users\dforth\PycharmProjects\clarity_scripts\scripts\parse_spectramax_seq_plate_quant.py", line 120, in _run
    self.add_plates_to_step()
  File "C:\Users\dforth\PycharmProjects\clarity_scripts\scripts\parse_spectramax_seq_plate_quant.py", line 72, in add_plates_to_step
    column_list['A','B','C']
NameError: name 'column_list' is not defined

[2018-Nov-15 08:55:22][SpectramaxOutput][INFO] Updating step 24-31255 with data: defaultdict(<class 'dict'>, {'LP9181114-QNT': {'A4': 11.668, 'B4': 12.953, 'C4': 11.956, 'D4': 14.602, 'E4': 15.004, 'F4': 13.887, 'G4': 9.784, 'H4': 9.227, 'A5': 9.264, 'B5': 17.582, 'C5': 12.502, 'D5': 8.349, 'E5': 19.791, 'F5': 12.696, 'G5': 13.008, 'H5': 12.371, 'A6': 13.612, 'B6': 14.669, 'C6': 14.631, 'D6': 15.86, 'E6': 13.383, 'F6': 9.6, 'G6': 9.344, 'A7': 13.487, 'B7': 18.704, 'C7': 17.042, 'D7': 10.437, 'E7': 9.78, 'F7': 51.478, 'G7': 29.193, 'H7': 40.868, 'A8': 31.263, 'B8': 92.617, 'C8': 24.526, 'D8': 20.771, 'E8': 15.419, 'F8': 13.558, 'G8': 13.504, 'H8': 20.026, 'A9': 20.408, 'B9': 14.256, 'C9': 14.809, 'D9': 13.044, 'E9': 16.158, 'F9': 17.959, 'G9': 14.0, 'A10': 16.957, 'B10': 10.44, 'C10': 19.174, 'D10': 14.89, 'E10': 13.281, 'F10': 18.997, 'G10': 15.905, 'H10': 11.266, 'A11': 17.499, 'B11': 19.764, 'C11': 16.318, 'D11': 10.108, 'E11': 17.18, 'F11': 18.287, 'G11': 15.628, 'H11': 15.328, 'A12': 10.231, 'B12': 18.013, 'C12': 17.457, 'D12': 16.377, 'E12': 12.438, 'F12': 15.503, 'G12': 21.822}})
[2018-Nov-15 08:55:27][SpectramaxOutput][CRITICAL] Encountered a TypeError exception: unsupported operand type(s) for +: 'int' and 'NoneType'
[2018-Nov-15 08:55:27][SpectramaxOutput][ERROR] Stack trace below:
Traceback (most recent call last):
  File "C:\Users\dforth\PycharmProjects\untitled\venv\lib\site-packages\clarity_scripts-0.9.dev0-py3.6.egg\EPPs\common.py", line 133, in run
    return self._run()
  File "C:\Users\dforth\PycharmProjects\clarity_scripts\scripts\parse_spectramax_seq_plate_quant.py", line 121, in _run
    self.average_replicates()
  File "C:\Users\dforth\PycharmProjects\clarity_scripts\scripts\parse_spectramax_seq_plate_quant.py", line 111, in average_replicates
    total = total + replicate
TypeError: unsupported operand type(s) for +: 'int' and 'NoneType'

[2018-Nov-15 08:56:21][SpectramaxOutput][INFO] Updating step 24-31255 with data: defaultdict(<class 'dict'>, {'LP9181114-QNT': {'A4': 11.668, 'B4': 12.953, 'C4': 11.956, 'D4': 14.602, 'E4': 15.004, 'F4': 13.887, 'G4': 9.784, 'H4': 9.227, 'A5': 9.264, 'B5': 17.582, 'C5': 12.502, 'D5': 8.349, 'E5': 19.791, 'F5': 12.696, 'G5': 13.008, 'H5': 12.371, 'A6': 13.612, 'B6': 14.669, 'C6': 14.631, 'D6': 15.86, 'E6': 13.383, 'F6': 9.6, 'G6': 9.344, 'A7': 13.487, 'B7': 18.704, 'C7': 17.042, 'D7': 10.437, 'E7': 9.78, 'F7': 51.478, 'G7': 29.193, 'H7': 40.868, 'A8': 31.263, 'B8': 92.617, 'C8': 24.526, 'D8': 20.771, 'E8': 15.419, 'F8': 13.558, 'G8': 13.504, 'H8': 20.026, 'A9': 20.408, 'B9': 14.256, 'C9': 14.809, 'D9': 13.044, 'E9': 16.158, 'F9': 17.959, 'G9': 14.0, 'A10': 16.957, 'B10': 10.44, 'C10': 19.174, 'D10': 14.89, 'E10': 13.281, 'F10': 18.997, 'G10': 15.905, 'H10': 11.266, 'A11': 17.499, 'B11': 19.764, 'C11': 16.318, 'D11': 10.108, 'E11': 17.18, 'F11': 18.287, 'G11': 15.628, 'H11': 15.328, 'A12': 10.231, 'B12': 18.013, 'C12': 17.457, 'D12': 16.377, 'E12': 12.438, 'F12': 15.503, 'G12': 21.822}})
[2018-Nov-15 08:56:21][SpectramaxOutput][CRITICAL] Encountered a NameError exception: name 'standard_wells' is not defined
[2018-Nov-15 08:56:21][SpectramaxOutput][ERROR] Stack trace below:
Traceback (most recent call last):
  File "C:\Users\dforth\PycharmProjects\untitled\venv\lib\site-packages\clarity_scripts-0.9.dev0-py3.6.egg\EPPs\common.py", line 133, in run
    return self._run()
  File "C:\Users\dforth\PycharmProjects\clarity_scripts\scripts\parse_spectramax_seq_plate_quant.py", line 123, in _run
    self.add_plates_to_step()
  File "C:\Users\dforth\PycharmProjects\clarity_scripts\scripts\parse_spectramax_seq_plate_quant.py", line 79, in add_plates_to_step
    print(standard_wells)
NameError: name 'standard_wells' is not defined

[2018-Nov-15 08:56:36][SpectramaxOutput][INFO] Updating step 24-31255 with data: defaultdict(<class 'dict'>, {'LP9181114-QNT': {'A4': 11.668, 'B4': 12.953, 'C4': 11.956, 'D4': 14.602, 'E4': 15.004, 'F4': 13.887, 'G4': 9.784, 'H4': 9.227, 'A5': 9.264, 'B5': 17.582, 'C5': 12.502, 'D5': 8.349, 'E5': 19.791, 'F5': 12.696, 'G5': 13.008, 'H5': 12.371, 'A6': 13.612, 'B6': 14.669, 'C6': 14.631, 'D6': 15.86, 'E6': 13.383, 'F6': 9.6, 'G6': 9.344, 'A7': 13.487, 'B7': 18.704, 'C7': 17.042, 'D7': 10.437, 'E7': 9.78, 'F7': 51.478, 'G7': 29.193, 'H7': 40.868, 'A8': 31.263, 'B8': 92.617, 'C8': 24.526, 'D8': 20.771, 'E8': 15.419, 'F8': 13.558, 'G8': 13.504, 'H8': 20.026, 'A9': 20.408, 'B9': 14.256, 'C9': 14.809, 'D9': 13.044, 'E9': 16.158, 'F9': 17.959, 'G9': 14.0, 'A10': 16.957, 'B10': 10.44, 'C10': 19.174, 'D10': 14.89, 'E10': 13.281, 'F10': 18.997, 'G10': 15.905, 'H10': 11.266, 'A11': 17.499, 'B11': 19.764, 'C11': 16.318, 'D11': 10.108, 'E11': 17.18, 'F11': 18.287, 'G11': 15.628, 'H11': 15.328, 'A12': 10.231, 'B12': 18.013, 'C12': 17.457, 'D12': 16.377, 'E12': 12.438, 'F12': 15.503, 'G12': 21.822}})
[2018-Nov-15 08:56:41][SpectramaxOutput][CRITICAL] Encountered a TypeError exception: unsupported operand type(s) for +: 'int' and 'NoneType'
[2018-Nov-15 08:56:41][SpectramaxOutput][ERROR] Stack trace below:
Traceback (most recent call last):
  File "C:\Users\dforth\PycharmProjects\untitled\venv\lib\site-packages\clarity_scripts-0.9.dev0-py3.6.egg\EPPs\common.py", line 133, in run
    return self._run()
  File "C:\Users\dforth\PycharmProjects\clarity_scripts\scripts\parse_spectramax_seq_plate_quant.py", line 124, in _run
    self.average_replicates()
  File "C:\Users\dforth\PycharmProjects\clarity_scripts\scripts\parse_spectramax_seq_plate_quant.py", line 114, in average_replicates
    total = total + replicate
TypeError: unsupported operand type(s) for +: 'int' and 'NoneType'

[2018-Nov-15 08:57:48][SpectramaxOutput][INFO] Updating step 24-31255 with data: defaultdict(<class 'dict'>, {'LP9181114-QNT': {'A4': 11.668, 'B4': 12.953, 'C4': 11.956, 'D4': 14.602, 'E4': 15.004, 'F4': 13.887, 'G4': 9.784, 'H4': 9.227, 'A5': 9.264, 'B5': 17.582, 'C5': 12.502, 'D5': 8.349, 'E5': 19.791, 'F5': 12.696, 'G5': 13.008, 'H5': 12.371, 'A6': 13.612, 'B6': 14.669, 'C6': 14.631, 'D6': 15.86, 'E6': 13.383, 'F6': 9.6, 'G6': 9.344, 'A7': 13.487, 'B7': 18.704, 'C7': 17.042, 'D7': 10.437, 'E7': 9.78, 'F7': 51.478, 'G7': 29.193, 'H7': 40.868, 'A8': 31.263, 'B8': 92.617, 'C8': 24.526, 'D8': 20.771, 'E8': 15.419, 'F8': 13.558, 'G8': 13.504, 'H8': 20.026, 'A9': 20.408, 'B9': 14.256, 'C9': 14.809, 'D9': 13.044, 'E9': 16.158, 'F9': 17.959, 'G9': 14.0, 'A10': 16.957, 'B10': 10.44, 'C10': 19.174, 'D10': 14.89, 'E10': 13.281, 'F10': 18.997, 'G10': 15.905, 'H10': 11.266, 'A11': 17.499, 'B11': 19.764, 'C11': 16.318, 'D11': 10.108, 'E11': 17.18, 'F11': 18.287, 'G11': 15.628, 'H11': 15.328, 'A12': 10.231, 'B12': 18.013, 'C12': 17.457, 'D12': 16.377, 'E12': 12.438, 'F12': 15.503, 'G12': 21.822}})
[2018-Nov-15 08:57:48][SpectramaxOutput][CRITICAL] Encountered a KeyError exception: 'B1'
[2018-Nov-15 08:57:48][SpectramaxOutput][ERROR] Stack trace below:
Traceback (most recent call last):
  File "C:\Users\dforth\PycharmProjects\untitled\venv\lib\site-packages\clarity_scripts-0.9.dev0-py3.6.egg\EPPs\common.py", line 133, in run
    return self._run()
  File "C:\Users\dforth\PycharmProjects\clarity_scripts\scripts\parse_spectramax_seq_plate_quant.py", line 122, in _run
    self.add_plates_to_step()
  File "C:\Users\dforth\PycharmProjects\clarity_scripts\scripts\parse_spectramax_seq_plate_quant.py", line 90, in add_plates_to_step
    artifact.udf['Picogreen Concentration (ng/ul)'] = self.plates[plate_name][coord]
KeyError: 'B1'

[2018-Nov-15 08:59:40][SpectramaxOutput][INFO] Updating step 24-31255 with data: defaultdict(<class 'dict'>, {'LP9181114-QNT': {'A4': 11.668, 'B4': 12.953, 'C4': 11.956, 'D4': 14.602, 'E4': 15.004, 'F4': 13.887, 'G4': 9.784, 'H4': 9.227, 'A5': 9.264, 'B5': 17.582, 'C5': 12.502, 'D5': 8.349, 'E5': 19.791, 'F5': 12.696, 'G5': 13.008, 'H5': 12.371, 'A6': 13.612, 'B6': 14.669, 'C6': 14.631, 'D6': 15.86, 'E6': 13.383, 'F6': 9.6, 'G6': 9.344, 'A7': 13.487, 'B7': 18.704, 'C7': 17.042, 'D7': 10.437, 'E7': 9.78, 'F7': 51.478, 'G7': 29.193, 'H7': 40.868, 'A8': 31.263, 'B8': 92.617, 'C8': 24.526, 'D8': 20.771, 'E8': 15.419, 'F8': 13.558, 'G8': 13.504, 'H8': 20.026, 'A9': 20.408, 'B9': 14.256, 'C9': 14.809, 'D9': 13.044, 'E9': 16.158, 'F9': 17.959, 'G9': 14.0, 'A10': 16.957, 'B10': 10.44, 'C10': 19.174, 'D10': 14.89, 'E10': 13.281, 'F10': 18.997, 'G10': 15.905, 'H10': 11.266, 'A11': 17.499, 'B11': 19.764, 'C11': 16.318, 'D11': 10.108, 'E11': 17.18, 'F11': 18.287, 'G11': 15.628, 'H11': 15.328, 'A12': 10.231, 'B12': 18.013, 'C12': 17.457, 'D12': 16.377, 'E12': 12.438, 'F12': 15.503, 'G12': 21.822}})
[2018-Nov-15 08:59:40][SpectramaxOutput][CRITICAL] Encountered a KeyError exception: 'B1'
[2018-Nov-15 08:59:40][SpectramaxOutput][ERROR] Stack trace below:
Traceback (most recent call last):
  File "C:\Users\dforth\PycharmProjects\untitled\venv\lib\site-packages\clarity_scripts-0.9.dev0-py3.6.egg\EPPs\common.py", line 133, in run
    return self._run()
  File "C:\Users\dforth\PycharmProjects\clarity_scripts\scripts\parse_spectramax_seq_plate_quant.py", line 122, in _run
    self.add_plates_to_step()
  File "C:\Users\dforth\PycharmProjects\clarity_scripts\scripts\parse_spectramax_seq_plate_quant.py", line 90, in add_plates_to_step
    artifact.udf['Picogreen Concentration (ng/ul)'] = self.plates[plate_name][coord]
KeyError: 'B1'

[2018-Nov-15 09:02:50][SpectramaxOutput][INFO] Updating step 24-31255 with data: defaultdict(<class 'dict'>, {'LP9181115-QNT': {'A4': 11.668, 'B4': 12.953, 'C4': 11.956, 'D4': 14.602, 'E4': 15.004, 'F4': 13.887, 'G4': 9.784, 'H4': 9.227, 'A5': 9.264, 'B5': 17.582, 'C5': 12.502, 'D5': 8.349, 'E5': 19.791, 'F5': 12.696, 'G5': 13.008, 'H5': 12.371, 'A6': 13.612, 'B6': 14.669, 'C6': 14.631, 'D6': 15.86, 'E6': 13.383, 'F6': 9.6, 'G6': 9.344, 'A7': 13.487, 'B7': 18.704, 'C7': 17.042, 'D7': 10.437, 'E7': 9.78, 'F7': 51.478, 'G7': 29.193, 'H7': 40.868, 'A8': 31.263, 'B8': 92.617, 'C8': 24.526, 'D8': 20.771, 'E8': 15.419, 'F8': 13.558, 'G8': 13.504, 'H8': 20.026, 'A9': 20.408, 'B9': 14.256, 'C9': 14.809, 'D9': 13.044, 'E9': 16.158, 'F9': 17.959, 'G9': 14.0, 'A10': 16.957, 'B10': 10.44, 'C10': 19.174, 'D10': 14.89, 'E10': 13.281, 'F10': 18.997, 'G10': 15.905, 'H10': 11.266, 'A11': 17.499, 'B11': 19.764, 'C11': 16.318, 'D11': 10.108, 'E11': 17.18, 'F11': 18.287, 'G11': 15.628, 'H11': 15.328, 'A12': 10.231, 'B12': 18.013, 'C12': 17.457, 'D12': 16.377, 'E12': 12.438, 'F12': 15.503, 'G12': 21.822}})
[2018-Nov-15 09:02:51][SpectramaxOutput][CRITICAL] Encountered a KeyError exception: 'B1'
[2018-Nov-15 09:02:51][SpectramaxOutput][ERROR] Stack trace below:
Traceback (most recent call last):
  File "C:\Users\dforth\PycharmProjects\untitled\venv\lib\site-packages\clarity_scripts-0.9.dev0-py3.6.egg\EPPs\common.py", line 133, in run
    return self._run()
  File "C:\Users\dforth\PycharmProjects\clarity_scripts\scripts\parse_spectramax_seq_plate_quant.py", line 122, in _run
    self.add_plates_to_step()
  File "C:\Users\dforth\PycharmProjects\clarity_scripts\scripts\parse_spectramax_seq_plate_quant.py", line 90, in add_plates_to_step
    artifact.udf['Picogreen Concentration (ng/ul)'] = self.plates[plate_name][coord]
KeyError: 'B1'

[2018-Nov-15 09:18:05][SpectramaxOutput][INFO] Updating step 24-31255 with data: defaultdict(<class 'dict'>, {'LP9181115-QNT': {'A4': 11.668, 'B4': 12.953, 'C4': 11.956, 'D4': 14.602, 'E4': 15.004, 'F4': 13.887, 'G4': 9.784, 'H4': 9.227, 'A5': 9.264, 'B5': 17.582, 'C5': 12.502, 'D5': 8.349, 'E5': 19.791, 'F5': 12.696, 'G5': 13.008, 'H5': 12.371, 'A6': 13.612, 'B6': 14.669, 'C6': 14.631, 'D6': 15.86, 'E6': 13.383, 'F6': 9.6, 'G6': 9.344, 'A7': 13.487, 'B7': 18.704, 'C7': 17.042, 'D7': 10.437, 'E7': 9.78, 'F7': 51.478, 'G7': 29.193, 'H7': 40.868, 'A8': 31.263, 'B8': 92.617, 'C8': 24.526, 'D8': 20.771, 'E8': 15.419, 'F8': 13.558, 'G8': 13.504, 'H8': 20.026, 'A9': 20.408, 'B9': 14.256, 'C9': 14.809, 'D9': 13.044, 'E9': 16.158, 'F9': 17.959, 'G9': 14.0, 'A10': 16.957, 'B10': 10.44, 'C10': 19.174, 'D10': 14.89, 'E10': 13.281, 'F10': 18.997, 'G10': 15.905, 'H10': 11.266, 'A11': 17.499, 'B11': 19.764, 'C11': 16.318, 'D11': 10.108, 'E11': 17.18, 'F11': 18.287, 'G11': 15.628, 'H11': 15.328, 'A12': 10.231, 'B12': 18.013, 'C12': 17.457, 'D12': 16.377, 'E12': 12.438, 'F12': 15.503, 'G12': 21.822}})
[2018-Nov-15 09:18:05][SpectramaxOutput][CRITICAL] Encountered a UnboundLocalError exception: local variable 'plate_name' referenced before assignment
[2018-Nov-15 09:18:05][SpectramaxOutput][ERROR] Stack trace below:
Traceback (most recent call last):
  File "C:\Users\dforth\PycharmProjects\untitled\venv\lib\site-packages\clarity_scripts-0.9.dev0-py3.6.egg\EPPs\common.py", line 133, in run
    return self._run()
  File "C:\Users\dforth\PycharmProjects\clarity_scripts\scripts\parse_spectramax_seq_plate_quant.py", line 123, in _run
    self.add_plates_to_step()
  File "C:\Users\dforth\PycharmProjects\clarity_scripts\scripts\parse_spectramax_seq_plate_quant.py", line 80, in add_plates_to_step
    print(self.plates[plate_name])
UnboundLocalError: local variable 'plate_name' referenced before assignment

[2018-Nov-15 09:18:29][SpectramaxOutput][INFO] Updating step 24-31255 with data: defaultdict(<class 'dict'>, {'LP9181115-QNT': {'A4': 11.668, 'B4': 12.953, 'C4': 11.956, 'D4': 14.602, 'E4': 15.004, 'F4': 13.887, 'G4': 9.784, 'H4': 9.227, 'A5': 9.264, 'B5': 17.582, 'C5': 12.502, 'D5': 8.349, 'E5': 19.791, 'F5': 12.696, 'G5': 13.008, 'H5': 12.371, 'A6': 13.612, 'B6': 14.669, 'C6': 14.631, 'D6': 15.86, 'E6': 13.383, 'F6': 9.6, 'G6': 9.344, 'A7': 13.487, 'B7': 18.704, 'C7': 17.042, 'D7': 10.437, 'E7': 9.78, 'F7': 51.478, 'G7': 29.193, 'H7': 40.868, 'A8': 31.263, 'B8': 92.617, 'C8': 24.526, 'D8': 20.771, 'E8': 15.419, 'F8': 13.558, 'G8': 13.504, 'H8': 20.026, 'A9': 20.408, 'B9': 14.256, 'C9': 14.809, 'D9': 13.044, 'E9': 16.158, 'F9': 17.959, 'G9': 14.0, 'A10': 16.957, 'B10': 10.44, 'C10': 19.174, 'D10': 14.89, 'E10': 13.281, 'F10': 18.997, 'G10': 15.905, 'H10': 11.266, 'A11': 17.499, 'B11': 19.764, 'C11': 16.318, 'D11': 10.108, 'E11': 17.18, 'F11': 18.287, 'G11': 15.628, 'H11': 15.328, 'A12': 10.231, 'B12': 18.013, 'C12': 17.457, 'D12': 16.377, 'E12': 12.438, 'F12': 15.503, 'G12': 21.822}})
[2018-Nov-15 09:18:29][SpectramaxOutput][CRITICAL] Encountered a UnboundLocalError exception: local variable 'plate_name' referenced before assignment
[2018-Nov-15 09:18:29][SpectramaxOutput][ERROR] Stack trace below:
Traceback (most recent call last):
  File "C:\Users\dforth\PycharmProjects\untitled\venv\lib\site-packages\clarity_scripts-0.9.dev0-py3.6.egg\EPPs\common.py", line 133, in run
    return self._run()
  File "C:\Users\dforth\PycharmProjects\clarity_scripts\scripts\parse_spectramax_seq_plate_quant.py", line 123, in _run
    self.add_plates_to_step()
  File "C:\Users\dforth\PycharmProjects\clarity_scripts\scripts\parse_spectramax_seq_plate_quant.py", line 80, in add_plates_to_step
    print(self.plates[plate_name])
UnboundLocalError: local variable 'plate_name' referenced before assignment

[2018-Nov-15 09:19:31][SpectramaxOutput][INFO] Updating step 24-31255 with data: defaultdict(<class 'dict'>, {'LP9181115-QNT': {'A4': 11.668, 'B4': 12.953, 'C4': 11.956, 'D4': 14.602, 'E4': 15.004, 'F4': 13.887, 'G4': 9.784, 'H4': 9.227, 'A5': 9.264, 'B5': 17.582, 'C5': 12.502, 'D5': 8.349, 'E5': 19.791, 'F5': 12.696, 'G5': 13.008, 'H5': 12.371, 'A6': 13.612, 'B6': 14.669, 'C6': 14.631, 'D6': 15.86, 'E6': 13.383, 'F6': 9.6, 'G6': 9.344, 'A7': 13.487, 'B7': 18.704, 'C7': 17.042, 'D7': 10.437, 'E7': 9.78, 'F7': 51.478, 'G7': 29.193, 'H7': 40.868, 'A8': 31.263, 'B8': 92.617, 'C8': 24.526, 'D8': 20.771, 'E8': 15.419, 'F8': 13.558, 'G8': 13.504, 'H8': 20.026, 'A9': 20.408, 'B9': 14.256, 'C9': 14.809, 'D9': 13.044, 'E9': 16.158, 'F9': 17.959, 'G9': 14.0, 'A10': 16.957, 'B10': 10.44, 'C10': 19.174, 'D10': 14.89, 'E10': 13.281, 'F10': 18.997, 'G10': 15.905, 'H10': 11.266, 'A11': 17.499, 'B11': 19.764, 'C11': 16.318, 'D11': 10.108, 'E11': 17.18, 'F11': 18.287, 'G11': 15.628, 'H11': 15.328, 'A12': 10.231, 'B12': 18.013, 'C12': 17.457, 'D12': 16.377, 'E12': 12.438, 'F12': 15.503, 'G12': 21.822}})
[2018-Nov-15 09:19:31][SpectramaxOutput][CRITICAL] Encountered a UnboundLocalError exception: local variable 'plate_name' referenced before assignment
[2018-Nov-15 09:19:31][SpectramaxOutput][ERROR] Stack trace below:
Traceback (most recent call last):
  File "C:\Users\dforth\PycharmProjects\untitled\venv\lib\site-packages\clarity_scripts-0.9.dev0-py3.6.egg\EPPs\common.py", line 133, in run
    return self._run()
  File "C:\Users\dforth\PycharmProjects\clarity_scripts\scripts\parse_spectramax_seq_plate_quant.py", line 123, in _run
    self.add_plates_to_step()
  File "C:\Users\dforth\PycharmProjects\clarity_scripts\scripts\parse_spectramax_seq_plate_quant.py", line 80, in add_plates_to_step
    print(self.plates[plate_name])
UnboundLocalError: local variable 'plate_name' referenced before assignment

[2018-Nov-15 09:19:39][SpectramaxOutput][INFO] Updating step 24-31255 with data: defaultdict(<class 'dict'>, {'LP9181115-QNT': {'A4': 11.668, 'B4': 12.953, 'C4': 11.956, 'D4': 14.602, 'E4': 15.004, 'F4': 13.887, 'G4': 9.784, 'H4': 9.227, 'A5': 9.264, 'B5': 17.582, 'C5': 12.502, 'D5': 8.349, 'E5': 19.791, 'F5': 12.696, 'G5': 13.008, 'H5': 12.371, 'A6': 13.612, 'B6': 14.669, 'C6': 14.631, 'D6': 15.86, 'E6': 13.383, 'F6': 9.6, 'G6': 9.344, 'A7': 13.487, 'B7': 18.704, 'C7': 17.042, 'D7': 10.437, 'E7': 9.78, 'F7': 51.478, 'G7': 29.193, 'H7': 40.868, 'A8': 31.263, 'B8': 92.617, 'C8': 24.526, 'D8': 20.771, 'E8': 15.419, 'F8': 13.558, 'G8': 13.504, 'H8': 20.026, 'A9': 20.408, 'B9': 14.256, 'C9': 14.809, 'D9': 13.044, 'E9': 16.158, 'F9': 17.959, 'G9': 14.0, 'A10': 16.957, 'B10': 10.44, 'C10': 19.174, 'D10': 14.89, 'E10': 13.281, 'F10': 18.997, 'G10': 15.905, 'H10': 11.266, 'A11': 17.499, 'B11': 19.764, 'C11': 16.318, 'D11': 10.108, 'E11': 17.18, 'F11': 18.287, 'G11': 15.628, 'H11': 15.328, 'A12': 10.231, 'B12': 18.013, 'C12': 17.457, 'D12': 16.377, 'E12': 12.438, 'F12': 15.503, 'G12': 21.822}})
[2018-Nov-15 09:19:40][SpectramaxOutput][CRITICAL] Encountered a KeyError exception: 'B1'
[2018-Nov-15 09:19:40][SpectramaxOutput][ERROR] Stack trace below:
Traceback (most recent call last):
  File "C:\Users\dforth\PycharmProjects\untitled\venv\lib\site-packages\clarity_scripts-0.9.dev0-py3.6.egg\EPPs\common.py", line 133, in run
    return self._run()
  File "C:\Users\dforth\PycharmProjects\clarity_scripts\scripts\parse_spectramax_seq_plate_quant.py", line 123, in _run
    self.add_plates_to_step()
  File "C:\Users\dforth\PycharmProjects\clarity_scripts\scripts\parse_spectramax_seq_plate_quant.py", line 91, in add_plates_to_step
    artifact.udf['Picogreen Concentration (ng/ul)'] = self.plates[plate_name][coord]
KeyError: 'B1'

[2018-Nov-15 09:23:33][SpectramaxOutput][INFO] Updating step 24-31255 with data: defaultdict(<class 'dict'>, {'LP9181115-QNT': {'A4': 11.668, 'B4': 12.953, 'C4': 11.956, 'D4': 14.602, 'E4': 15.004, 'F4': 13.887, 'G4': 9.784, 'H4': 9.227, 'A5': 9.264, 'B5': 17.582, 'C5': 12.502, 'D5': 8.349, 'E5': 19.791, 'F5': 12.696, 'G5': 13.008, 'H5': 12.371, 'A6': 13.612, 'B6': 14.669, 'C6': 14.631, 'D6': 15.86, 'E6': 13.383, 'F6': 9.6, 'G6': 9.344, 'A7': 13.487, 'B7': 18.704, 'C7': 17.042, 'D7': 10.437, 'E7': 9.78, 'F7': 51.478, 'G7': 29.193, 'H7': 40.868, 'A8': 31.263, 'B8': 92.617, 'C8': 24.526, 'D8': 20.771, 'E8': 15.419, 'F8': 13.558, 'G8': 13.504, 'H8': 20.026, 'A9': 20.408, 'B9': 14.256, 'C9': 14.809, 'D9': 13.044, 'E9': 16.158, 'F9': 17.959, 'G9': 14.0, 'A10': 16.957, 'B10': 10.44, 'C10': 19.174, 'D10': 14.89, 'E10': 13.281, 'F10': 18.997, 'G10': 15.905, 'H10': 11.266, 'A11': 17.499, 'B11': 19.764, 'C11': 16.318, 'D11': 10.108, 'E11': 17.18, 'F11': 18.287, 'G11': 15.628, 'H11': 15.328, 'A12': 10.231, 'B12': 18.013, 'C12': 17.457, 'D12': 16.377, 'E12': 12.438, 'F12': 15.503, 'G12': 21.822}})
[2018-Nov-15 09:23:51][SpectramaxOutput][CRITICAL] Encountered a TypeError exception: unsupported operand type(s) for +: 'int' and 'NoneType'
[2018-Nov-15 09:23:51][SpectramaxOutput][ERROR] Stack trace below:
Traceback (most recent call last):
  File "C:\Users\dforth\PycharmProjects\untitled\venv\lib\site-packages\clarity_scripts-0.9.dev0-py3.6.egg\EPPs\common.py", line 133, in run
    return self._run()
  File "C:\Users\dforth\PycharmProjects\clarity_scripts\scripts\parse_spectramax_seq_plate_quant.py", line 126, in _run
    self.average_replicates()
  File "C:\Users\dforth\PycharmProjects\clarity_scripts\scripts\parse_spectramax_seq_plate_quant.py", line 116, in average_replicates
    total = total + replicate
TypeError: unsupported operand type(s) for +: 'int' and 'NoneType'

[2018-Nov-15 09:26:42][SpectramaxOutput][INFO] Updating step 24-31255 with data: defaultdict(<class 'dict'>, {'LP9181115-QNT': {'A4': 11.668, 'B4': 12.953, 'C4': 11.956, 'D4': 14.602, 'E4': 15.004, 'F4': 13.887, 'G4': 9.784, 'H4': 9.227, 'A5': 9.264, 'B5': 17.582, 'C5': 12.502, 'D5': 8.349, 'E5': 19.791, 'F5': 12.696, 'G5': 13.008, 'H5': 12.371, 'A6': 13.612, 'B6': 14.669, 'C6': 14.631, 'D6': 15.86, 'E6': 13.383, 'F6': 9.6, 'G6': 9.344, 'A7': 13.487, 'B7': 18.704, 'C7': 17.042, 'D7': 10.437, 'E7': 9.78, 'F7': 51.478, 'G7': 29.193, 'H7': 40.868, 'A8': 31.263, 'B8': 92.617, 'C8': 24.526, 'D8': 20.771, 'E8': 15.419, 'F8': 13.558, 'G8': 13.504, 'H8': 20.026, 'A9': 20.408, 'B9': 14.256, 'C9': 14.809, 'D9': 13.044, 'E9': 16.158, 'F9': 17.959, 'G9': 14.0, 'A10': 16.957, 'B10': 10.44, 'C10': 19.174, 'D10': 14.89, 'E10': 13.281, 'F10': 18.997, 'G10': 15.905, 'H10': 11.266, 'A11': 17.499, 'B11': 19.764, 'C11': 16.318, 'D11': 10.108, 'E11': 17.18, 'F11': 18.287, 'G11': 15.628, 'H11': 15.328, 'A12': 10.231, 'B12': 18.013, 'C12': 17.457, 'D12': 16.377, 'E12': 12.438, 'F12': 15.503, 'G12': 21.822}})
[2018-Nov-15 09:27:00][SpectramaxOutput][CRITICAL] Encountered a TypeError exception: unsupported operand type(s) for +: 'int' and 'NoneType'
[2018-Nov-15 09:27:00][SpectramaxOutput][ERROR] Stack trace below:
Traceback (most recent call last):
  File "C:\Users\dforth\PycharmProjects\untitled\venv\lib\site-packages\clarity_scripts-0.9.dev0-py3.6.egg\EPPs\common.py", line 133, in run
    return self._run()
  File "C:\Users\dforth\PycharmProjects\clarity_scripts\scripts\parse_spectramax_seq_plate_quant.py", line 126, in _run
    self.average_replicates()
  File "C:\Users\dforth\PycharmProjects\clarity_scripts\scripts\parse_spectramax_seq_plate_quant.py", line 116, in average_replicates
    total = total + replicate
TypeError: unsupported operand type(s) for +: 'int' and 'NoneType'

[2018-Nov-15 09:27:53][SpectramaxOutput][INFO] Updating step 24-31255 with data: defaultdict(<class 'dict'>, {'LP9181115-QNT': {'A4': 11.668, 'B4': 12.953, 'C4': 11.956, 'D4': 14.602, 'E4': 15.004, 'F4': 13.887, 'G4': 9.784, 'H4': 9.227, 'A5': 9.264, 'B5': 17.582, 'C5': 12.502, 'D5': 8.349, 'E5': 19.791, 'F5': 12.696, 'G5': 13.008, 'H5': 12.371, 'A6': 13.612, 'B6': 14.669, 'C6': 14.631, 'D6': 15.86, 'E6': 13.383, 'F6': 9.6, 'G6': 9.344, 'A7': 13.487, 'B7': 18.704, 'C7': 17.042, 'D7': 10.437, 'E7': 9.78, 'F7': 51.478, 'G7': 29.193, 'H7': 40.868, 'A8': 31.263, 'B8': 92.617, 'C8': 24.526, 'D8': 20.771, 'E8': 15.419, 'F8': 13.558, 'G8': 13.504, 'H8': 20.026, 'A9': 20.408, 'B9': 14.256, 'C9': 14.809, 'D9': 13.044, 'E9': 16.158, 'F9': 17.959, 'G9': 14.0, 'A10': 16.957, 'B10': 10.44, 'C10': 19.174, 'D10': 14.89, 'E10': 13.281, 'F10': 18.997, 'G10': 15.905, 'H10': 11.266, 'A11': 17.499, 'B11': 19.764, 'C11': 16.318, 'D11': 10.108, 'E11': 17.18, 'F11': 18.287, 'G11': 15.628, 'H11': 15.328, 'A12': 10.231, 'B12': 18.013, 'C12': 17.457, 'D12': 16.377, 'E12': 12.438, 'F12': 15.503, 'G12': 21.822}})
[2018-Nov-15 09:28:11][SpectramaxOutput][CRITICAL] Encountered a TypeError exception: unsupported operand type(s) for +: 'int' and 'NoneType'
[2018-Nov-15 09:28:11][SpectramaxOutput][ERROR] Stack trace below:
Traceback (most recent call last):
  File "C:\Users\dforth\PycharmProjects\untitled\venv\lib\site-packages\clarity_scripts-0.9.dev0-py3.6.egg\EPPs\common.py", line 133, in run
    return self._run()
  File "C:\Users\dforth\PycharmProjects\clarity_scripts\scripts\parse_spectramax_seq_plate_quant.py", line 126, in _run
    self.average_replicates()
  File "C:\Users\dforth\PycharmProjects\clarity_scripts\scripts\parse_spectramax_seq_plate_quant.py", line 116, in average_replicates
    total = total + replicate
TypeError: unsupported operand type(s) for +: 'int' and 'NoneType'

[2018-Nov-15 09:29:15][SpectramaxOutput][INFO] Updating step 24-31255 with data: defaultdict(<class 'dict'>, {'LP9181115-QNT': {'A4': 11.668, 'B4': 12.953, 'C4': 11.956, 'D4': 14.602, 'E4': 15.004, 'F4': 13.887, 'G4': 9.784, 'H4': 9.227, 'A5': 9.264, 'B5': 17.582, 'C5': 12.502, 'D5': 8.349, 'E5': 19.791, 'F5': 12.696, 'G5': 13.008, 'H5': 12.371, 'A6': 13.612, 'B6': 14.669, 'C6': 14.631, 'D6': 15.86, 'E6': 13.383, 'F6': 9.6, 'G6': 9.344, 'A7': 13.487, 'B7': 18.704, 'C7': 17.042, 'D7': 10.437, 'E7': 9.78, 'F7': 51.478, 'G7': 29.193, 'H7': 40.868, 'A8': 31.263, 'B8': 92.617, 'C8': 24.526, 'D8': 20.771, 'E8': 15.419, 'F8': 13.558, 'G8': 13.504, 'H8': 20.026, 'A9': 20.408, 'B9': 14.256, 'C9': 14.809, 'D9': 13.044, 'E9': 16.158, 'F9': 17.959, 'G9': 14.0, 'A10': 16.957, 'B10': 10.44, 'C10': 19.174, 'D10': 14.89, 'E10': 13.281, 'F10': 18.997, 'G10': 15.905, 'H10': 11.266, 'A11': 17.499, 'B11': 19.764, 'C11': 16.318, 'D11': 10.108, 'E11': 17.18, 'F11': 18.287, 'G11': 15.628, 'H11': 15.328, 'A12': 10.231, 'B12': 18.013, 'C12': 17.457, 'D12': 16.377, 'E12': 12.438, 'F12': 15.503, 'G12': 21.822}})
[2018-Nov-15 09:29:33][SpectramaxOutput][CRITICAL] Encountered a TypeError exception: unsupported operand type(s) for +: 'int' and 'NoneType'
[2018-Nov-15 09:29:33][SpectramaxOutput][ERROR] Stack trace below:
Traceback (most recent call last):
  File "C:\Users\dforth\PycharmProjects\untitled\venv\lib\site-packages\clarity_scripts-0.9.dev0-py3.6.egg\EPPs\common.py", line 133, in run
    return self._run()
  File "C:\Users\dforth\PycharmProjects\clarity_scripts\scripts\parse_spectramax_seq_plate_quant.py", line 127, in _run
    self.average_replicates()
  File "C:\Users\dforth\PycharmProjects\clarity_scripts\scripts\parse_spectramax_seq_plate_quant.py", line 117, in average_replicates
    total = total + replicate
TypeError: unsupported operand type(s) for +: 'int' and 'NoneType'

[2018-Nov-15 09:30:20][SpectramaxOutput][INFO] Updating step 24-31255 with data: defaultdict(<class 'dict'>, {'LP9181115-QNT': {'A4': 11.668, 'B4': 12.953, 'C4': 11.956, 'D4': 14.602, 'E4': 15.004, 'F4': 13.887, 'G4': 9.784, 'H4': 9.227, 'A5': 9.264, 'B5': 17.582, 'C5': 12.502, 'D5': 8.349, 'E5': 19.791, 'F5': 12.696, 'G5': 13.008, 'H5': 12.371, 'A6': 13.612, 'B6': 14.669, 'C6': 14.631, 'D6': 15.86, 'E6': 13.383, 'F6': 9.6, 'G6': 9.344, 'A7': 13.487, 'B7': 18.704, 'C7': 17.042, 'D7': 10.437, 'E7': 9.78, 'F7': 51.478, 'G7': 29.193, 'H7': 40.868, 'A8': 31.263, 'B8': 92.617, 'C8': 24.526, 'D8': 20.771, 'E8': 15.419, 'F8': 13.558, 'G8': 13.504, 'H8': 20.026, 'A9': 20.408, 'B9': 14.256, 'C9': 14.809, 'D9': 13.044, 'E9': 16.158, 'F9': 17.959, 'G9': 14.0, 'A10': 16.957, 'B10': 10.44, 'C10': 19.174, 'D10': 14.89, 'E10': 13.281, 'F10': 18.997, 'G10': 15.905, 'H10': 11.266, 'A11': 17.499, 'B11': 19.764, 'C11': 16.318, 'D11': 10.108, 'E11': 17.18, 'F11': 18.287, 'G11': 15.628, 'H11': 15.328, 'A12': 10.231, 'B12': 18.013, 'C12': 17.457, 'D12': 16.377, 'E12': 12.438, 'F12': 15.503, 'G12': 21.822}})
[2018-Nov-15 09:30:25][SpectramaxOutput][CRITICAL] Encountered a TypeError exception: unsupported operand type(s) for +: 'int' and 'NoneType'
[2018-Nov-15 09:30:25][SpectramaxOutput][ERROR] Stack trace below:
Traceback (most recent call last):
  File "C:\Users\dforth\PycharmProjects\untitled\venv\lib\site-packages\clarity_scripts-0.9.dev0-py3.6.egg\EPPs\common.py", line 133, in run
    return self._run()
  File "C:\Users\dforth\PycharmProjects\clarity_scripts\scripts\parse_spectramax_seq_plate_quant.py", line 127, in _run
    self.average_replicates()
  File "C:\Users\dforth\PycharmProjects\clarity_scripts\scripts\parse_spectramax_seq_plate_quant.py", line 117, in average_replicates
    total = total + replicate
TypeError: unsupported operand type(s) for +: 'int' and 'NoneType'

[2018-Nov-15 09:31:22][SpectramaxOutput][INFO] Updating step 24-31255 with data: defaultdict(<class 'dict'>, {'LP9181115-QNT': {'A4': 11.668, 'B4': 12.953, 'C4': 11.956, 'D4': 14.602, 'E4': 15.004, 'F4': 13.887, 'G4': 9.784, 'H4': 9.227, 'A5': 9.264, 'B5': 17.582, 'C5': 12.502, 'D5': 8.349, 'E5': 19.791, 'F5': 12.696, 'G5': 13.008, 'H5': 12.371, 'A6': 13.612, 'B6': 14.669, 'C6': 14.631, 'D6': 15.86, 'E6': 13.383, 'F6': 9.6, 'G6': 9.344, 'A7': 13.487, 'B7': 18.704, 'C7': 17.042, 'D7': 10.437, 'E7': 9.78, 'F7': 51.478, 'G7': 29.193, 'H7': 40.868, 'A8': 31.263, 'B8': 92.617, 'C8': 24.526, 'D8': 20.771, 'E8': 15.419, 'F8': 13.558, 'G8': 13.504, 'H8': 20.026, 'A9': 20.408, 'B9': 14.256, 'C9': 14.809, 'D9': 13.044, 'E9': 16.158, 'F9': 17.959, 'G9': 14.0, 'A10': 16.957, 'B10': 10.44, 'C10': 19.174, 'D10': 14.89, 'E10': 13.281, 'F10': 18.997, 'G10': 15.905, 'H10': 11.266, 'A11': 17.499, 'B11': 19.764, 'C11': 16.318, 'D11': 10.108, 'E11': 17.18, 'F11': 18.287, 'G11': 15.628, 'H11': 15.328, 'A12': 10.231, 'B12': 18.013, 'C12': 17.457, 'D12': 16.377, 'E12': 12.438, 'F12': 15.503, 'G12': 21.822}})
[2018-Nov-15 09:31:23][SpectramaxOutput][CRITICAL] Encountered a KeyError exception: 'B1'
[2018-Nov-15 09:31:23][SpectramaxOutput][ERROR] Stack trace below:
Traceback (most recent call last):
  File "C:\Users\dforth\PycharmProjects\untitled\venv\lib\site-packages\clarity_scripts-0.9.dev0-py3.6.egg\EPPs\common.py", line 133, in run
    return self._run()
  File "C:\Users\dforth\PycharmProjects\clarity_scripts\scripts\parse_spectramax_seq_plate_quant.py", line 125, in _run
    self.add_plates_to_step()
  File "C:\Users\dforth\PycharmProjects\clarity_scripts\scripts\parse_spectramax_seq_plate_quant.py", line 93, in add_plates_to_step
    artifact.udf['Picogreen Concentration (ng/ul)'] = self.plates[plate_name][coord]
KeyError: 'B1'

[2018-Nov-15 09:32:45][SpectramaxOutput][INFO] Updating step 24-31255 with data: defaultdict(<class 'dict'>, {'LP9181115-QNT': {'A4': 11.668, 'B4': 12.953, 'C4': 11.956, 'D4': 14.602, 'E4': 15.004, 'F4': 13.887, 'G4': 9.784, 'H4': 9.227, 'A5': 9.264, 'B5': 17.582, 'C5': 12.502, 'D5': 8.349, 'E5': 19.791, 'F5': 12.696, 'G5': 13.008, 'H5': 12.371, 'A6': 13.612, 'B6': 14.669, 'C6': 14.631, 'D6': 15.86, 'E6': 13.383, 'F6': 9.6, 'G6': 9.344, 'A7': 13.487, 'B7': 18.704, 'C7': 17.042, 'D7': 10.437, 'E7': 9.78, 'F7': 51.478, 'G7': 29.193, 'H7': 40.868, 'A8': 31.263, 'B8': 92.617, 'C8': 24.526, 'D8': 20.771, 'E8': 15.419, 'F8': 13.558, 'G8': 13.504, 'H8': 20.026, 'A9': 20.408, 'B9': 14.256, 'C9': 14.809, 'D9': 13.044, 'E9': 16.158, 'F9': 17.959, 'G9': 14.0, 'A10': 16.957, 'B10': 10.44, 'C10': 19.174, 'D10': 14.89, 'E10': 13.281, 'F10': 18.997, 'G10': 15.905, 'H10': 11.266, 'A11': 17.499, 'B11': 19.764, 'C11': 16.318, 'D11': 10.108, 'E11': 17.18, 'F11': 18.287, 'G11': 15.628, 'H11': 15.328, 'A12': 10.231, 'B12': 18.013, 'C12': 17.457, 'D12': 16.377, 'E12': 12.438, 'F12': 15.503, 'G12': 21.822}})
[2018-Nov-15 09:33:02][SpectramaxOutput][CRITICAL] Encountered a TypeError exception: unsupported operand type(s) for +: 'int' and 'NoneType'
[2018-Nov-15 09:33:02][SpectramaxOutput][ERROR] Stack trace below:
Traceback (most recent call last):
  File "C:\Users\dforth\PycharmProjects\untitled\venv\lib\site-packages\clarity_scripts-0.9.dev0-py3.6.egg\EPPs\common.py", line 133, in run
    return self._run()
  File "C:\Users\dforth\PycharmProjects\clarity_scripts\scripts\parse_spectramax_seq_plate_quant.py", line 126, in _run
    self.average_replicates()
  File "C:\Users\dforth\PycharmProjects\clarity_scripts\scripts\parse_spectramax_seq_plate_quant.py", line 116, in average_replicates
    total = total + replicate
TypeError: unsupported operand type(s) for +: 'int' and 'NoneType'

[2018-Nov-15 09:33:49][SpectramaxOutput][INFO] Updating step 24-31255 with data: defaultdict(<class 'dict'>, {'LP9181115-QNT': {'A4': 11.668, 'B4': 12.953, 'C4': 11.956, 'D4': 14.602, 'E4': 15.004, 'F4': 13.887, 'G4': 9.784, 'H4': 9.227, 'A5': 9.264, 'B5': 17.582, 'C5': 12.502, 'D5': 8.349, 'E5': 19.791, 'F5': 12.696, 'G5': 13.008, 'H5': 12.371, 'A6': 13.612, 'B6': 14.669, 'C6': 14.631, 'D6': 15.86, 'E6': 13.383, 'F6': 9.6, 'G6': 9.344, 'A7': 13.487, 'B7': 18.704, 'C7': 17.042, 'D7': 10.437, 'E7': 9.78, 'F7': 51.478, 'G7': 29.193, 'H7': 40.868, 'A8': 31.263, 'B8': 92.617, 'C8': 24.526, 'D8': 20.771, 'E8': 15.419, 'F8': 13.558, 'G8': 13.504, 'H8': 20.026, 'A9': 20.408, 'B9': 14.256, 'C9': 14.809, 'D9': 13.044, 'E9': 16.158, 'F9': 17.959, 'G9': 14.0, 'A10': 16.957, 'B10': 10.44, 'C10': 19.174, 'D10': 14.89, 'E10': 13.281, 'F10': 18.997, 'G10': 15.905, 'H10': 11.266, 'A11': 17.499, 'B11': 19.764, 'C11': 16.318, 'D11': 10.108, 'E11': 17.18, 'F11': 18.287, 'G11': 15.628, 'H11': 15.328, 'A12': 10.231, 'B12': 18.013, 'C12': 17.457, 'D12': 16.377, 'E12': 12.438, 'F12': 15.503, 'G12': 21.822}})
[2018-Nov-15 09:34:07][SpectramaxOutput][CRITICAL] Encountered a TypeError exception: unsupported operand type(s) for +: 'int' and 'NoneType'
[2018-Nov-15 09:34:07][SpectramaxOutput][ERROR] Stack trace below:
Traceback (most recent call last):
  File "C:\Users\dforth\PycharmProjects\untitled\venv\lib\site-packages\clarity_scripts-0.9.dev0-py3.6.egg\EPPs\common.py", line 133, in run
    return self._run()
  File "C:\Users\dforth\PycharmProjects\clarity_scripts\scripts\parse_spectramax_seq_plate_quant.py", line 126, in _run
    self.average_replicates()
  File "C:\Users\dforth\PycharmProjects\clarity_scripts\scripts\parse_spectramax_seq_plate_quant.py", line 116, in average_replicates
    total = total + replicate
TypeError: unsupported operand type(s) for +: 'int' and 'NoneType'

[2018-Nov-15 09:34:09][SpectramaxOutput][INFO] Updating step 24-31255 with data: defaultdict(<class 'dict'>, {'LP9181115-QNT': {'A4': 11.668, 'B4': 12.953, 'C4': 11.956, 'D4': 14.602, 'E4': 15.004, 'F4': 13.887, 'G4': 9.784, 'H4': 9.227, 'A5': 9.264, 'B5': 17.582, 'C5': 12.502, 'D5': 8.349, 'E5': 19.791, 'F5': 12.696, 'G5': 13.008, 'H5': 12.371, 'A6': 13.612, 'B6': 14.669, 'C6': 14.631, 'D6': 15.86, 'E6': 13.383, 'F6': 9.6, 'G6': 9.344, 'A7': 13.487, 'B7': 18.704, 'C7': 17.042, 'D7': 10.437, 'E7': 9.78, 'F7': 51.478, 'G7': 29.193, 'H7': 40.868, 'A8': 31.263, 'B8': 92.617, 'C8': 24.526, 'D8': 20.771, 'E8': 15.419, 'F8': 13.558, 'G8': 13.504, 'H8': 20.026, 'A9': 20.408, 'B9': 14.256, 'C9': 14.809, 'D9': 13.044, 'E9': 16.158, 'F9': 17.959, 'G9': 14.0, 'A10': 16.957, 'B10': 10.44, 'C10': 19.174, 'D10': 14.89, 'E10': 13.281, 'F10': 18.997, 'G10': 15.905, 'H10': 11.266, 'A11': 17.499, 'B11': 19.764, 'C11': 16.318, 'D11': 10.108, 'E11': 17.18, 'F11': 18.287, 'G11': 15.628, 'H11': 15.328, 'A12': 10.231, 'B12': 18.013, 'C12': 17.457, 'D12': 16.377, 'E12': 12.438, 'F12': 15.503, 'G12': 21.822}})
[2018-Nov-15 09:34:27][SpectramaxOutput][CRITICAL] Encountered a TypeError exception: unsupported operand type(s) for +: 'int' and 'NoneType'
[2018-Nov-15 09:34:27][SpectramaxOutput][ERROR] Stack trace below:
Traceback (most recent call last):
  File "C:\Users\dforth\PycharmProjects\untitled\venv\lib\site-packages\clarity_scripts-0.9.dev0-py3.6.egg\EPPs\common.py", line 133, in run
    return self._run()
  File "C:\Users\dforth\PycharmProjects\clarity_scripts\scripts\parse_spectramax_seq_plate_quant.py", line 126, in _run
    self.average_replicates()
  File "C:\Users\dforth\PycharmProjects\clarity_scripts\scripts\parse_spectramax_seq_plate_quant.py", line 116, in average_replicates
    total = total + replicate
TypeError: unsupported operand type(s) for +: 'int' and 'NoneType'

[2018-Nov-15 09:35:59][SpectramaxOutput][INFO] Updating step 24-31255 with data: defaultdict(<class 'dict'>, {'LP9181115-QNT': {'A4': 11.668, 'B4': 12.953, 'C4': 11.956, 'D4': 14.602, 'E4': 15.004, 'F4': 13.887, 'G4': 9.784, 'H4': 9.227, 'A5': 9.264, 'B5': 17.582, 'C5': 12.502, 'D5': 8.349, 'E5': 19.791, 'F5': 12.696, 'G5': 13.008, 'H5': 12.371, 'A6': 13.612, 'B6': 14.669, 'C6': 14.631, 'D6': 15.86, 'E6': 13.383, 'F6': 9.6, 'G6': 9.344, 'A7': 13.487, 'B7': 18.704, 'C7': 17.042, 'D7': 10.437, 'E7': 9.78, 'F7': 51.478, 'G7': 29.193, 'H7': 40.868, 'A8': 31.263, 'B8': 92.617, 'C8': 24.526, 'D8': 20.771, 'E8': 15.419, 'F8': 13.558, 'G8': 13.504, 'H8': 20.026, 'A9': 20.408, 'B9': 14.256, 'C9': 14.809, 'D9': 13.044, 'E9': 16.158, 'F9': 17.959, 'G9': 14.0, 'A10': 16.957, 'B10': 10.44, 'C10': 19.174, 'D10': 14.89, 'E10': 13.281, 'F10': 18.997, 'G10': 15.905, 'H10': 11.266, 'A11': 17.499, 'B11': 19.764, 'C11': 16.318, 'D11': 10.108, 'E11': 17.18, 'F11': 18.287, 'G11': 15.628, 'H11': 15.328, 'A12': 10.231, 'B12': 18.013, 'C12': 17.457, 'D12': 16.377, 'E12': 12.438, 'F12': 15.503, 'G12': 21.822}})
[2018-Nov-15 09:36:16][SpectramaxOutput][CRITICAL] Encountered a TypeError exception: unsupported operand type(s) for +: 'int' and 'NoneType'
[2018-Nov-15 09:36:16][SpectramaxOutput][ERROR] Stack trace below:
Traceback (most recent call last):
  File "C:\Users\dforth\PycharmProjects\untitled\venv\lib\site-packages\clarity_scripts-0.9.dev0-py3.6.egg\EPPs\common.py", line 133, in run
    return self._run()
  File "C:\Users\dforth\PycharmProjects\clarity_scripts\scripts\parse_spectramax_seq_plate_quant.py", line 127, in _run
    self.average_replicates()
  File "C:\Users\dforth\PycharmProjects\clarity_scripts\scripts\parse_spectramax_seq_plate_quant.py", line 117, in average_replicates
    total = total + replicate
TypeError: unsupported operand type(s) for +: 'int' and 'NoneType'

[2018-Nov-15 09:37:15][SpectramaxOutput][INFO] Updating step 24-31255 with data: defaultdict(<class 'dict'>, {'LP9181115-QNT': {'A4': 11.668, 'B4': 12.953, 'C4': 11.956, 'D4': 14.602, 'E4': 15.004, 'F4': 13.887, 'G4': 9.784, 'H4': 9.227, 'A5': 9.264, 'B5': 17.582, 'C5': 12.502, 'D5': 8.349, 'E5': 19.791, 'F5': 12.696, 'G5': 13.008, 'H5': 12.371, 'A6': 13.612, 'B6': 14.669, 'C6': 14.631, 'D6': 15.86, 'E6': 13.383, 'F6': 9.6, 'G6': 9.344, 'A7': 13.487, 'B7': 18.704, 'C7': 17.042, 'D7': 10.437, 'E7': 9.78, 'F7': 51.478, 'G7': 29.193, 'H7': 40.868, 'A8': 31.263, 'B8': 92.617, 'C8': 24.526, 'D8': 20.771, 'E8': 15.419, 'F8': 13.558, 'G8': 13.504, 'H8': 20.026, 'A9': 20.408, 'B9': 14.256, 'C9': 14.809, 'D9': 13.044, 'E9': 16.158, 'F9': 17.959, 'G9': 14.0, 'A10': 16.957, 'B10': 10.44, 'C10': 19.174, 'D10': 14.89, 'E10': 13.281, 'F10': 18.997, 'G10': 15.905, 'H10': 11.266, 'A11': 17.499, 'B11': 19.764, 'C11': 16.318, 'D11': 10.108, 'E11': 17.18, 'F11': 18.287, 'G11': 15.628, 'H11': 15.328, 'A12': 10.231, 'B12': 18.013, 'C12': 17.457, 'D12': 16.377, 'E12': 12.438, 'F12': 15.503, 'G12': 21.822}})
[2018-Nov-15 09:37:33][SpectramaxOutput][CRITICAL] Encountered a TypeError exception: unsupported operand type(s) for +: 'int' and 'NoneType'
[2018-Nov-15 09:37:33][SpectramaxOutput][ERROR] Stack trace below:
Traceback (most recent call last):
  File "C:\Users\dforth\PycharmProjects\untitled\venv\lib\site-packages\clarity_scripts-0.9.dev0-py3.6.egg\EPPs\common.py", line 133, in run
    return self._run()
  File "C:\Users\dforth\PycharmProjects\clarity_scripts\scripts\parse_spectramax_seq_plate_quant.py", line 126, in _run
    self.average_replicates()
  File "C:\Users\dforth\PycharmProjects\clarity_scripts\scripts\parse_spectramax_seq_plate_quant.py", line 116, in average_replicates
    total = total + replicate
TypeError: unsupported operand type(s) for +: 'int' and 'NoneType'

[2018-Nov-15 09:40:00][SpectramaxOutput][INFO] Updating step 24-31255 with data: defaultdict(<class 'dict'>, {'LP9181115-QNT': {'A4': 11.668, 'B4': 12.953, 'C4': 11.956, 'D4': 14.602, 'E4': 15.004, 'F4': 13.887, 'G4': 9.784, 'H4': 9.227, 'A5': 9.264, 'B5': 17.582, 'C5': 12.502, 'D5': 8.349, 'E5': 19.791, 'F5': 12.696, 'G5': 13.008, 'H5': 12.371, 'A6': 13.612, 'B6': 14.669, 'C6': 14.631, 'D6': 15.86, 'E6': 13.383, 'F6': 9.6, 'G6': 9.344, 'A7': 13.487, 'B7': 18.704, 'C7': 17.042, 'D7': 10.437, 'E7': 9.78, 'F7': 51.478, 'G7': 29.193, 'H7': 40.868, 'A8': 31.263, 'B8': 92.617, 'C8': 24.526, 'D8': 20.771, 'E8': 15.419, 'F8': 13.558, 'G8': 13.504, 'H8': 20.026, 'A9': 20.408, 'B9': 14.256, 'C9': 14.809, 'D9': 13.044, 'E9': 16.158, 'F9': 17.959, 'G9': 14.0, 'A10': 16.957, 'B10': 10.44, 'C10': 19.174, 'D10': 14.89, 'E10': 13.281, 'F10': 18.997, 'G10': 15.905, 'H10': 11.266, 'A11': 17.499, 'B11': 19.764, 'C11': 16.318, 'D11': 10.108, 'E11': 17.18, 'F11': 18.287, 'G11': 15.628, 'H11': 15.328, 'A12': 10.231, 'B12': 18.013, 'C12': 17.457, 'D12': 16.377, 'E12': 12.438, 'F12': 15.503, 'G12': 21.822}})
[2018-Nov-15 09:40:14][SpectramaxOutput][CRITICAL] Encountered a KeyError exception: Artifact(https://egclaritydev.mvm.ed.ac.uk/api/v2/artifacts/14C-1074PA1?state=91800)
[2018-Nov-15 09:40:14][SpectramaxOutput][ERROR] Stack trace below:
Traceback (most recent call last):
  File "C:\Users\dforth\PycharmProjects\untitled\venv\lib\site-packages\clarity_scripts-0.9.dev0-py3.6.egg\EPPs\common.py", line 133, in run
    return self._run()
  File "C:\Users\dforth\PycharmProjects\clarity_scripts\scripts\parse_spectramax_seq_plate_quant.py", line 128, in _run
    self.average_replicates()
  File "C:\Users\dforth\PycharmProjects\clarity_scripts\scripts\parse_spectramax_seq_plate_quant.py", line 112, in average_replicates
    print("replicates",input_artifacts_replicates[input_output_map[0]['uri']])
KeyError: Artifact(https://egclaritydev.mvm.ed.ac.uk/api/v2/artifacts/14C-1074PA1?state=91800)

[2018-Nov-15 09:43:03][SpectramaxOutput][INFO] Updating step 24-31255 with data: defaultdict(<class 'dict'>, {'LP9181115-QNT': {'A4': 11.668, 'B4': 12.953, 'C4': 11.956, 'D4': 14.602, 'E4': 15.004, 'F4': 13.887, 'G4': 9.784, 'H4': 9.227, 'A5': 9.264, 'B5': 17.582, 'C5': 12.502, 'D5': 8.349, 'E5': 19.791, 'F5': 12.696, 'G5': 13.008, 'H5': 12.371, 'A6': 13.612, 'B6': 14.669, 'C6': 14.631, 'D6': 15.86, 'E6': 13.383, 'F6': 9.6, 'G6': 9.344, 'A7': 13.487, 'B7': 18.704, 'C7': 17.042, 'D7': 10.437, 'E7': 9.78, 'F7': 51.478, 'G7': 29.193, 'H7': 40.868, 'A8': 31.263, 'B8': 92.617, 'C8': 24.526, 'D8': 20.771, 'E8': 15.419, 'F8': 13.558, 'G8': 13.504, 'H8': 20.026, 'A9': 20.408, 'B9': 14.256, 'C9': 14.809, 'D9': 13.044, 'E9': 16.158, 'F9': 17.959, 'G9': 14.0, 'A10': 16.957, 'B10': 10.44, 'C10': 19.174, 'D10': 14.89, 'E10': 13.281, 'F10': 18.997, 'G10': 15.905, 'H10': 11.266, 'A11': 17.499, 'B11': 19.764, 'C11': 16.318, 'D11': 10.108, 'E11': 17.18, 'F11': 18.287, 'G11': 15.628, 'H11': 15.328, 'A12': 10.231, 'B12': 18.013, 'C12': 17.457, 'D12': 16.377, 'E12': 12.438, 'F12': 15.503, 'G12': 21.822}})
[2018-Nov-15 09:43:22][SpectramaxOutput][CRITICAL] Encountered a TypeError exception: unsupported operand type(s) for +: 'int' and 'NoneType'
[2018-Nov-15 09:43:22][SpectramaxOutput][ERROR] Stack trace below:
Traceback (most recent call last):
  File "C:\Users\dforth\PycharmProjects\untitled\venv\lib\site-packages\clarity_scripts-0.9.dev0-py3.6.egg\EPPs\common.py", line 133, in run
    return self._run()
  File "C:\Users\dforth\PycharmProjects\clarity_scripts\scripts\parse_spectramax_seq_plate_quant.py", line 129, in _run
    self.average_replicates()
  File "C:\Users\dforth\PycharmProjects\clarity_scripts\scripts\parse_spectramax_seq_plate_quant.py", line 119, in average_replicates
    total = total + replicate
TypeError: unsupported operand type(s) for +: 'int' and 'NoneType'

[2018-Nov-15 09:44:02][SpectramaxOutput][INFO] Updating step 24-31255 with data: defaultdict(<class 'dict'>, {'LP9181115-QNT': {'A4': 11.668, 'B4': 12.953, 'C4': 11.956, 'D4': 14.602, 'E4': 15.004, 'F4': 13.887, 'G4': 9.784, 'H4': 9.227, 'A5': 9.264, 'B5': 17.582, 'C5': 12.502, 'D5': 8.349, 'E5': 19.791, 'F5': 12.696, 'G5': 13.008, 'H5': 12.371, 'A6': 13.612, 'B6': 14.669, 'C6': 14.631, 'D6': 15.86, 'E6': 13.383, 'F6': 9.6, 'G6': 9.344, 'A7': 13.487, 'B7': 18.704, 'C7': 17.042, 'D7': 10.437, 'E7': 9.78, 'F7': 51.478, 'G7': 29.193, 'H7': 40.868, 'A8': 31.263, 'B8': 92.617, 'C8': 24.526, 'D8': 20.771, 'E8': 15.419, 'F8': 13.558, 'G8': 13.504, 'H8': 20.026, 'A9': 20.408, 'B9': 14.256, 'C9': 14.809, 'D9': 13.044, 'E9': 16.158, 'F9': 17.959, 'G9': 14.0, 'A10': 16.957, 'B10': 10.44, 'C10': 19.174, 'D10': 14.89, 'E10': 13.281, 'F10': 18.997, 'G10': 15.905, 'H10': 11.266, 'A11': 17.499, 'B11': 19.764, 'C11': 16.318, 'D11': 10.108, 'E11': 17.18, 'F11': 18.287, 'G11': 15.628, 'H11': 15.328, 'A12': 10.231, 'B12': 18.013, 'C12': 17.457, 'D12': 16.377, 'E12': 12.438, 'F12': 15.503, 'G12': 21.822}})
[2018-Nov-15 09:44:21][SpectramaxOutput][CRITICAL] Encountered a TypeError exception: unsupported operand type(s) for +: 'int' and 'NoneType'
[2018-Nov-15 09:44:21][SpectramaxOutput][ERROR] Stack trace below:
Traceback (most recent call last):
  File "C:\Users\dforth\PycharmProjects\untitled\venv\lib\site-packages\clarity_scripts-0.9.dev0-py3.6.egg\EPPs\common.py", line 133, in run
    return self._run()
  File "C:\Users\dforth\PycharmProjects\clarity_scripts\scripts\parse_spectramax_seq_plate_quant.py", line 129, in _run
    self.average_replicates()
  File "C:\Users\dforth\PycharmProjects\clarity_scripts\scripts\parse_spectramax_seq_plate_quant.py", line 119, in average_replicates
    total = total + replicate
TypeError: unsupported operand type(s) for +: 'int' and 'NoneType'

[2018-Nov-15 09:46:04][SpectramaxOutput][INFO] Updating step 24-31255 with data: defaultdict(<class 'dict'>, {'LP9181115-QNT': {'A4': 11.668, 'B4': 12.953, 'C4': 11.956, 'D4': 14.602, 'E4': 15.004, 'F4': 13.887, 'G4': 9.784, 'H4': 9.227, 'A5': 9.264, 'B5': 17.582, 'C5': 12.502, 'D5': 8.349, 'E5': 19.791, 'F5': 12.696, 'G5': 13.008, 'H5': 12.371, 'A6': 13.612, 'B6': 14.669, 'C6': 14.631, 'D6': 15.86, 'E6': 13.383, 'F6': 9.6, 'G6': 9.344, 'A7': 13.487, 'B7': 18.704, 'C7': 17.042, 'D7': 10.437, 'E7': 9.78, 'F7': 51.478, 'G7': 29.193, 'H7': 40.868, 'A8': 31.263, 'B8': 92.617, 'C8': 24.526, 'D8': 20.771, 'E8': 15.419, 'F8': 13.558, 'G8': 13.504, 'H8': 20.026, 'A9': 20.408, 'B9': 14.256, 'C9': 14.809, 'D9': 13.044, 'E9': 16.158, 'F9': 17.959, 'G9': 14.0, 'A10': 16.957, 'B10': 10.44, 'C10': 19.174, 'D10': 14.89, 'E10': 13.281, 'F10': 18.997, 'G10': 15.905, 'H10': 11.266, 'A11': 17.499, 'B11': 19.764, 'C11': 16.318, 'D11': 10.108, 'E11': 17.18, 'F11': 18.287, 'G11': 15.628, 'H11': 15.328, 'A12': 10.231, 'B12': 18.013, 'C12': 17.457, 'D12': 16.377, 'E12': 12.438, 'F12': 15.503, 'G12': 21.822}})
