[2018-Dec-03 17:14:36][AssignNextStep][CRITICAL] Encountered a UnboundLocalError exception: local variable 'imp_next_step_object' referenced before assignment
[2018-Dec-03 17:14:36][AssignNextStep][ERROR] Stack trace below:
Traceback (most recent call last):
  File "C:\Users\dforth\PycharmProjects\untitled\venv\lib\site-packages\clarity_scripts-0.9.dev0-py3.6.egg\EPPs\common.py", line 136, in run
    return self._run()
  File "C:\Users\dforth\PycharmProjects\clarity_scripts\scripts\next_step_assignment_imp_ssqc.py", line 47, in _run
    next_action['step'] = imp_next_step_object
UnboundLocalError: local variable 'imp_next_step_object' referenced before assignment

[2018-Dec-03 17:32:22][AssignNextStep][CRITICAL] Encountered a UnboundLocalError exception: local variable 'imp_next_step_object' referenced before assignment
[2018-Dec-03 17:32:22][AssignNextStep][ERROR] Stack trace below:
Traceback (most recent call last):
  File "C:\Users\dforth\PycharmProjects\untitled\venv\lib\site-packages\clarity_scripts-0.9.dev0-py3.6.egg\EPPs\common.py", line 136, in run
    return self._run()
  File "C:\Users\dforth\PycharmProjects\clarity_scripts\scripts\next_step_assignment_imp_ssqc.py", line 57, in _run
    next_action['step'] = imp_next_step_object
UnboundLocalError: local variable 'imp_next_step_object' referenced before assignment

[2018-Dec-03 17:35:34][AssignNextStep][CRITICAL] Encountered a HTTPError exception: 404: Step not found: 0
[2018-Dec-03 17:35:34][AssignNextStep][ERROR] Stack trace below:
Traceback (most recent call last):
  File "C:\Users\dforth\PycharmProjects\untitled\venv\lib\site-packages\clarity_scripts-0.9.dev0-py3.6.egg\EPPs\common.py", line 136, in run
    return self._run()
  File "C:\Users\dforth\PycharmProjects\clarity_scripts\scripts\next_step_assignment_imp_ssqc.py", line 27, in _run
    actions = self.process.step.actions
  File "C:\Users\dforth\PycharmProjects\untitled\venv\lib\site-packages\pyclarity_lims\descriptors.py", line 891, in __get__
    instance.get()
  File "C:\Users\dforth\PycharmProjects\untitled\venv\lib\site-packages\pyclarity_lims\entities.py", line 86, in get
    self.root = self.lims.get(self.uri)
  File "C:\Users\dforth\PycharmProjects\untitled\venv\lib\site-packages\pyclarity_lims\lims.py", line 96, in get
    return self.parse_response(r)
  File "C:\Users\dforth\PycharmProjects\untitled\venv\lib\site-packages\pyclarity_lims\lims.py", line 209, in parse_response
    self.validate_response(response, accept_status_codes)
  File "C:\Users\dforth\PycharmProjects\untitled\venv\lib\site-packages\pyclarity_lims\lims.py", line 202, in validate_response
    raise requests.exceptions.HTTPError(message)
requests.exceptions.HTTPError: 404: Step not found: 0

